Workbook
Name __PRN2: {"adj95mult",#N/A,FALSE,"COMPCO";"adj95est",#N/A,FALSE,"COMPCO"}
Name __PRN2: {"adj95mult",#N/A,FALSE,"COMPCO";"adj95est",#N/A,FALSE,"COMPCO"}
Name _PRN2: {"adj95mult",#N/A,FALSE,"COMPCO";"adj95est",#N/A,FALSE,"COMPCO"}
Name _PRN2: {"adj95mult",#N/A,FALSE,"COMPCO";"adj95est",#N/A,FALSE,"COMPCO"}
Name aa: {"DCF1",#N/A,FALSE,"SIERRA DCF";"MATRIX1",#N/A,FALSE,"SIERRA DCF"}
Name aa: {"DCF1",#N/A,FALSE,"SIERRA DCF";"MATRIX1",#N/A,FALSE,"SIERRA DCF"}
Name aaa: {"adj95mult",#N/A,FALSE,"COMPCO";"adj95est",#N/A,FALSE,"COMPCO"}
Name aaa: {"adj95mult",#N/A,FALSE,"COMPCO";"adj95est",#N/A,FALSE,"COMPCO"}
Name casds: {"DCF1",#N/A,FALSE,"SIERRA DCF";"MATRIX1",#N/A,FALSE,"SIERRA DCF"}
Name casds: {"DCF1",#N/A,FALSE,"SIERRA DCF";"MATRIX1",#N/A,FALSE,"SIERRA DCF"}
Name dafdsf: {"qchm_dcf",#N/A,FALSE,"QCHMDCF2";"qchm_terminal",#N/A,FALSE,"QCHMDCF2"}
Name dafdsf: {"qchm_dcf",#N/A,FALSE,"QCHMDCF2";"qchm_terminal",#N/A,FALSE,"QCHMDCF2"}
Name ddd: {"adj95mult",#N/A,FALSE,"COMPCO";"adj95est",#N/A,FALSE,"COMPCO"}
Name ddd: {"adj95mult",#N/A,FALSE,"COMPCO";"adj95est",#N/A,FALSE,"COMPCO"}
Name dfa: {"Acq_matrix",#N/A,FALSE,"Acquisition Matrix"}
Name dfa: {"Acq_matrix",#N/A,FALSE,"Acquisition Matrix"}
Name dfhgfgdjgd: {"Matrix",#N/A,FALSE,"ACQMTRX";"Fees",#N/A,FALSE,"ACQMTRX"}
Name dfhgfgdjgd: {"Matrix",#N/A,FALSE,"ACQMTRX";"Fees",#N/A,FALSE,"ACQMTRX"}
Name Div_Industrial: {"adj95mult",#N/A,FALSE,"COMPCO";"adj95est",#N/A,FALSE,"COMPCO"}
Name Div_Industrial: {"adj95mult",#N/A,FALSE,"COMPCO";"adj95est",#N/A,FALSE,"COMPCO"}
Name e: {"adj95mult",#N/A,FALSE,"COMPCO";"adj95est",#N/A,FALSE,"COMPCO"}
Name e: {"adj95mult",#N/A,FALSE,"COMPCO";"adj95est",#N/A,FALSE,"COMPCO"}
Name fgefgef: {"qchm_dcf",#N/A,FALSE,"QCHMDCF2";"qchm_terminal",#N/A,FALSE,"QCHMDCF2"}
Name fgefgef: {"qchm_dcf",#N/A,FALSE,"QCHMDCF2";"qchm_terminal",#N/A,FALSE,"QCHMDCF2"}
Name fhrghgrd: {"DCF1",#N/A,FALSE,"SIERRA DCF";"MATRIX1",#N/A,FALSE,"SIERRA DCF"}
Name fhrghgrd: {"DCF1",#N/A,FALSE,"SIERRA DCF";"MATRIX1",#N/A,FALSE,"SIERRA DCF"}
Name fsdfdfa: {"page1",#N/A,FALSE,"BHCOMPC5";"page2",#N/A,FALSE,"BHCOMPC5";"page3",#N/A,FALSE,"BHCOMPC5";"page4",#N/A,FALSE,"BHCOMPC5"}
Name fsdfdfa: {"page1",#N/A,FALSE,"BHCOMPC5";"page2",#N/A,FALSE,"BHCOMPC5";"page3",#N/A,FALSE,"BHCOMPC5";"page4",#N/A,FALSE,"BHCOMPC5"}
Name g: {"page1",#N/A,FALSE,"BHCOMPC5";"page2",#N/A,FALSE,"BHCOMPC5";"page3",#N/A,FALSE,"BHCOMPC5";"page4",#N/A,FALSE,"BHCOMPC5"}
Name g: {"page1",#N/A,FALSE,"BHCOMPC5";"page2",#N/A,FALSE,"BHCOMPC5";"page3",#N/A,FALSE,"BHCOMPC5";"page4",#N/A,FALSE,"BHCOMPC5"}
Name hhgjghj: {"DCF1",#N/A,FALSE,"SIERRA DCF";"MATRIX1",#N/A,FALSE,"SIERRA DCF"}
Name hhgjghj: {"DCF1",#N/A,FALSE,"SIERRA DCF";"MATRIX1",#N/A,FALSE,"SIERRA DCF"}
Name htgrer: {"page1",#N/A,FALSE,"BHCOMPC5";"page2",#N/A,FALSE,"BHCOMPC5";"page3",#N/A,FALSE,"BHCOMPC5";"page4",#N/A,FALSE,"BHCOMPC5"}
Name htgrer: {"page1",#N/A,FALSE,"BHCOMPC5";"page2",#N/A,FALSE,"BHCOMPC5";"page3",#N/A,FALSE,"BHCOMPC5";"page4",#N/A,FALSE,"BHCOMPC5"}
Name i: {"DCF1",#N/A,FALSE,"SIERRA DCF";"MATRIX1",#N/A,FALSE,"SIERRA DCF"}
Name i: {"DCF1",#N/A,FALSE,"SIERRA DCF";"MATRIX1",#N/A,FALSE,"SIERRA DCF"}
Name j: {"EVA",#N/A,FALSE,"EVA";"WACC",#N/A,FALSE,"WACC"}
Name j: {"EVA",#N/A,FALSE,"EVA";"WACC",#N/A,FALSE,"WACC"}
Name k: {"DCF","UPSIDE CASE",FALSE,"Sheet1";"DCF","BASE CASE",FALSE,"Sheet1";"DCF","DOWNSIDE CASE",FALSE,"Sheet1"}
Name k: {"DCF","UPSIDE CASE",FALSE,"Sheet1";"DCF","BASE CASE",FALSE,"Sheet1";"DCF","DOWNSIDE CASE",FALSE,"Sheet1"}
Name nhjythh: {"DCF","UPSIDE CASE",FALSE,"Sheet1";"DCF","BASE CASE",FALSE,"Sheet1";"DCF","DOWNSIDE CASE",FALSE,"Sheet1"}
Name nhjythh: {"DCF","UPSIDE CASE",FALSE,"Sheet1";"DCF","BASE CASE",FALSE,"Sheet1";"DCF","DOWNSIDE CASE",FALSE,"Sheet1"}
Name sadd: {"DCF","UPSIDE CASE",FALSE,"Sheet1";"DCF","BASE CASE",FALSE,"Sheet1";"DCF","DOWNSIDE CASE",FALSE,"Sheet1"}
Name sadd: {"DCF","UPSIDE CASE",FALSE,"Sheet1";"DCF","BASE CASE",FALSE,"Sheet1";"DCF","DOWNSIDE CASE",FALSE,"Sheet1"}
Name sdasd: {"EVA",#N/A,FALSE,"EVA";"WACC",#N/A,FALSE,"WACC"}
Name sdasd: {"EVA",#N/A,FALSE,"EVA";"WACC",#N/A,FALSE,"WACC"}
Name segfsdvgfsd: {"page1",#N/A,FALSE,"BHCOMPC5";"page2",#N/A,FALSE,"BHCOMPC5";"page3",#N/A,FALSE,"BHCOMPC5";"page4",#N/A,FALSE,"BHCOMPC5"}
Name segfsdvgfsd: {"page1",#N/A,FALSE,"BHCOMPC5";"page2",#N/A,FALSE,"BHCOMPC5";"page3",#N/A,FALSE,"BHCOMPC5";"page4",#N/A,FALSE,"BHCOMPC5"}
Name sfads: {"EVA",#N/A,FALSE,"EVA";"WACC",#N/A,FALSE,"WACC"}
Name sfads: {"EVA",#N/A,FALSE,"EVA";"WACC",#N/A,FALSE,"WACC"}
Name sgag: {"page1",#N/A,FALSE,"BHCOMPC5";"page2",#N/A,FALSE,"BHCOMPC5";"page3",#N/A,FALSE,"BHCOMPC5";"page4",#N/A,FALSE,"BHCOMPC5"}
Name sgag: {"page1",#N/A,FALSE,"BHCOMPC5";"page2",#N/A,FALSE,"BHCOMPC5";"page3",#N/A,FALSE,"BHCOMPC5";"page4",#N/A,FALSE,"BHCOMPC5"}
Name ss: {"DCF1",#N/A,FALSE,"SIERRA DCF";"MATRIX1",#N/A,FALSE,"SIERRA DCF"}
Name ss: {"DCF1",#N/A,FALSE,"SIERRA DCF";"MATRIX1",#N/A,FALSE,"SIERRA DCF"}
Name w: {"DCF1",#N/A,FALSE,"SIERRA DCF";"MATRIX1",#N/A,FALSE,"SIERRA DCF"}
Name w: {"DCF1",#N/A,FALSE,"SIERRA DCF";"MATRIX1",#N/A,FALSE,"SIERRA DCF"}
Name WACC3: {"adj95mult",#N/A,FALSE,"COMPCO";"adj95est",#N/A,FALSE,"COMPCO"}
Name WACC3: {"adj95mult",#N/A,FALSE,"COMPCO";"adj95est",#N/A,FALSE,"COMPCO"}
Name wrn.Acquisition_matrix.: {"Acq_matrix",#N/A,FALSE,"Acquisition Matrix"}
Name wrn.Acquisition_matrix.: {"Acq_matrix",#N/A,FALSE,"Acquisition Matrix"}

Sheet CoverPage
C7: Financial Modeling & DCF Valuation - Meta Platforms

Sheet Assumption
C2: Scenario | D2: 1 | E2: =IF(D2=1,C12,IF(D2=2,C13,IF(D2=3,C14,"NA"))) -> Base Case
G5: Forecasting
B6: x | C6: Assumption | D6: For the Year Ended (FYE)
D7: 2023 | E7: =D7+1 -> 2024 | F7: =E7+1 -> 2025 | G7: =F7+1 -> 2026 | H7: =G7+1 -> 2027 | I7: =H7+1 -> 2028 | J7: =I7+1 -> 2029 | K7: =J7+1 -> 2030
C9: Revenue
C11: Daily Active People | G11: =CHOOSE($D$2,G12,G13,G14) -> 0.06284816 | H11: =CHOOSE($D$2,H12,H13,H14) -> 0.06284816 | I11: =CHOOSE($D$2,I12,I13,I14) -> 0.06284816 | J11: =CHOOSE($D$2,J12,J13,J14) -> 0.06284816 | K11: =CHOOSE($D$2,K12,K13,K14) -> 0.06284816
C12: Base Case | G12: 0.06284816 | H12: 0.06284816 | I12: 0.06284816 | J12: 0.06284816 | K12: 0.06284816
C13: Best Case | G13: 0.08 | H13: 0.08 | I13: 0.08 | J13: 0.08 | K13: 0.08 | M13: 0.02
C14: Worst Case | G14: 0.04 | H14: 0.04 | I14: 0.04 | J14: 0.04 | K14: 0.04 | M14: -0.02
C16: Average Revenue Per Person | G16: =CHOOSE($D$2,G17,G18,G19) -> 0.14963859 | H16: =CHOOSE($D$2,H17,H18,H19) -> 0.14963859 | I16: =CHOOSE($D$2,I17,I18,I19) -> 0.14963859 | J16: =CHOOSE($D$2,J17,J18,J19) -> 0.14963859 | K16: =CHOOSE($D$2,K17,K18,K19) -> 0.14963859
C17: Base Case | G17: 0.14963859 | H17: 0.14963859 | I17: 0.14963859 | J17: 0.14963859 | K17: 0.14963859
C18: Best Case | G18: 0.18 | H18: 0.18 | I18: 0.18 | J18: 0.18 | K18: 0.18 | M18: 0.03
C19: Worst Case | G19: 0.12 | H19: 0.12 | I19: 0.12 | J19: 0.12 | K19: 0.12 | M19: -0.03
C21: Op Exp
C22: Cost of Revenue | G22: -0.18526086 | H22: -0.18526086 | I22: -0.18526086 | J22: -0.18526086 | K22: -0.18526086
C23: Research and development exp | G23: -0.27915034 | H23: -0.27915034 | I23: -0.27915034 | J23: -0.27915034 | K23: -0.27915034
C24: Marketing and sales exp | G24: -0.073276608 | H24: -0.073276608 | I24: -0.073276608 | J24: -0.073276608 | K24: -0.073276608
C25: General and administrative exp | G25: -0.068080799 | H25: -0.068080799 | I25: -0.068080799 | J25: -0.068080799 | K25: -0.068080799
C27: Tax Rate | D27: 0.21 | E27: 0.21 | F27: 0.21 | G27: 0.21 | H27: 0.21 | I27: 0.21 | J27: 0.21 | K27: 0.21
C29: D&A
C30: CapEx | G30: -0.34678005 | H30: -0.34678005 | I30: -0.34678005 | J30: -0.34678005 | K30: -0.34678005
C31: Depn % of PPE | G31: 0.10422186 | H31: 0.10422186 | I31: 0.10422186 | J31: 0.10422186 | K31: 0.10422186
C32: Ammortization | D32: 161 | E32: 211 | F32: 615 | G32: 1259 | H32: 1162 | I32: 771 | J32: 39 | K32: 27
C33: Purchase of Intangible | G33: 0 | H33: 0 | I33: 0 | J33: 0 | K33: 0
C35: Equity
C36: Dividend Per Share | E36: =0.5*4 -> 2 | F36: =0.525*4 -> 2.1 | G36: =F36 -> 2.1 | H36: =G36 -> 2.1 | I36: =H36 -> 2.1 | J36: =I36 -> 2.1 | K36: =J36 -> 2.1
C37: Share outstanding | E37: =2190+344 -> 2534 | F37: =2187+343 -> 2530 | G37: =2187+343 -> 2530 | H37: =2187+343 -> 2530 | I37: =2187+343 -> 2530 | J37: =2187+343 -> 2530 | K37: =2187+343 -> 2530
C38: Issuance | G38: 0 | H38: 0 | I38: 0 | J38: 0 | K38: 0
C39: Repurchaseor Buyback | G39: 0 | H39: 0 | I39: 0 | J39: 0 | K39: 0
C41: WC
C42: Inventory | G42: 0 | H42: 0 | I42: 0 | J42: 0 | K42: 0
C43: Prepaid Exp | G43: 7361 | H43: 7361 | I43: 7361 | J43: 7361 | K43: 7361
C44: Accrued Expenses | G44: 30729 | H44: 30729 | I44: 30729 | J44: 30729 | K44: 30729
C45: No of Days | D45: 365 | E45: 365 | F45: 365 | G45: 365 | H45: 365 | I45: 365 | J45: 365 | K45: 365
C46: DSO | E46: =Assumption!E45/WC!E21 -> 36.791554 | F46: =Assumption!F45/WC!F21 -> 33.384988 | G46: 35.088271 | H46: 35.088271 | I46: 35.088271 | J46: 35.088271 | K46: 35.088271
C47: DIH | E47: =IFERROR(Assumption!E45/WC!E22,"n.a.") -> n.a. | F47: =IFERROR(Assumption!F45/WC!F22,"n.a.") -> n.a. | G47: n.a. | H47: n.a. | I47: n.a. | J47: n.a. | K47: n.a.
C48: DPO | E48: =Assumption!E45/WC!E24 -> 75.853586 | F48: =Assumption!F45/WC!F24 -> 83.649827 | G48: 79.751706 | H48: 79.751706 | I48: 79.751706 | J48: 79.751706 | K48: 79.751706
C50: LT Debt
C51: Isssuance | G51: 0 | H51: 0 | I51: 0 | J51: 0 | K51: 0
C52: Repayment | G52: 0 | H52: -2750 | I52: -1500 | J52: -1000 | K52: -5000
...

Sheet Operating Model - IS, BS, CF
D1: 2 | E1: 3 | F1: 4 | G1: 5 | H1: 6 | I1: 7 | J1: 8 | K1: 9
C2: Dropdown | G2: Forecasting
B3: x | C3: Income statement | D3: For the Year Ended (FYE) | N3: hard punced
D4: 2023 | E4: =D4+1 -> 2024 | F4: =E4+1 -> 2025 | G4: =F4+1 -> 2026 | H4: =G4+1 -> 2027 | I4: =H4+1 -> 2028 | J4: =I4+1 -> 2029 | K4: =J4+1 -> 2030 | N4: Formula
C5: Revenue | D5: 134902 | E5: 164501 | F5: 200966 | G5: =Revenue!S12 -> 244418.24 | H5: =Revenue!T12 -> 298652.51 | I5: =Revenue!U12 -> 364920.89 | J5: =Revenue!V12 -> 445893.64 | K5: =Revenue!W12 -> 544833.55 | O5: Revenue Projection
C6: growth (%) | E6: =E5/D5-1 -> 0.21941113 | F6: =F5/E5-1 -> 0.22167038 | O6: Historical Growth | P6: Done
C7: Cost of Revenue | D7: -25959 | E7: -30161 | F7: -36175 | G7: =Assumption!G22*G5 -> -45281.133 | H7: =Assumption!H22*H5 -> -55328.621 | I7: =Assumption!I22*I5 -> -67605.558 | J7: =Assumption!J22*J5 -> -82606.64 | K7: =Assumption!K22*K5 -> -100936.33 | O7: Transcripts / Managements Est
C8: % of sales | D8: =D7/D5 -> -0.19242858 | E8: =E7/E5 -> -0.18334843 | F8: =F7/F5 -> -0.18000557 | O8: Revenue model | P8: Done
C9: Gross Profit | D9: =D5+D7 -> 108943 | E9: =E5+E7 -> 134340 | F9: =F5+F7 -> 164791 | G9: =G5+G7 -> 199137.11 | H9: =H5+H7 -> 243323.89 | I9: =I5+I7 -> 297315.33 | J9: =J5+J7 -> 363287 | K9: =K5+K7 -> 443897.22 | O9: Consensus model
C10: SG&A
C11: Research and development exp | D11: -38483 | E11: -43873 | F11: -57372 | G11: =Assumption!G23*G5 -> -68229.434 | H11: =Assumption!H23*H5 -> -83368.949 | I11: =Assumption!I23*I5 -> -101867.79 | J11: =Assumption!J23*J5 -> -124471.36 | K11: =Assumption!K23*K5 -> -152090.47
C12: % of sales | D12: =D11/D5 -> -0.28526634 | E12: =E11/E5 -> -0.26670355 | F12: =F11/F5 -> -0.28548113
C13: Marketing and sales exp | D13: -12301 | E13: -11347 | F13: -11991 | G13: =Assumption!G24*G5 -> -17910.14 | H13: =Assumption!H24*H5 -> -21884.243 | I13: =Assumption!I24*I5 -> -26740.165 | J13: =Assumption!J24*J5 -> -32673.574 | K13: =Assumption!K24*K5 -> -39923.554
C14: % of sales | D14: =D13/D5 -> -0.091184712 | E14: =E13/E5 -> -0.068978304 | F14: =F13/F5 -> -0.059666809
C15: General and administrative exp | D15: -11408 | E15: -9740 | F15: -12152 | G15: =Assumption!G25*G5 -> -16640.189 | H15: =Assumption!H25*H5 -> -20332.502 | I15: =Assumption!I25*I5 -> -24844.106 | J15: =Assumption!J25*J5 -> -30356.796 | K15: =Assumption!K25*K5 -> -37092.703
C16: % of sales | D16: =D15/D5 -> -0.084565092 | E16: =E15/E5 -> -0.059209367 | F16: =F15/F5 -> -0.06046794
C17: Total Operating Exp | D17: =D15+D13+D11 -> -62192 | E17: =E15+E13+E11 -> -64960 | F17: =F15+F13+F11 -> -81515 | G17: =G15+G13+G11 -> -102779.76 | H17: =H15+H13+H11 -> -125585.69 | I17: =I15+I13+I11 -> -153452.06 | J17: =J15+J13+J11 -> -187501.73 | K17: =K15+K13+K11 -> -229106.73 | P17: Circular Ref
C18: Op Income (EBIT) | D18: =D9+D17 -> 46751 | E18: =E9+E17 -> 69380 | F18: =F9+F17 -> 83276 | G18: =G9+G17 -> 96357.343 | H18: =H9+H17 -> 117738.19 | I18: =I9+I17 -> 143863.27 | J18: =J9+J17 -> 175785.27 | K18: =K9+K17 -> 214790.49
C19: Interest Income / (Expense) | D19: 677 | E19: 1283 | F19: 2656 | G19: =Debt!G29 -> -1509.7824 | H19: =Debt!H29 -> -1353.8384 | I19: =Debt!I29 -> -946.64721 | J19: =Debt!J29 -> -480.19961 | K19: =Debt!K29 -> 53.782535 | P19: A>B
C20: Profit Before Tax (PBT) | D20: =D18+D19 -> 47428 | E20: =E18+E19 -> 70663 | F20: =F18+F19 -> 85932 | G20: =G18+G19 -> 94847.56 | H20: =H18+H19 -> 116384.36 | I20: =I18+I19 -> 142916.62 | J20: =J18+J19 -> 175305.07 | K20: =K18+K19 -> 214844.27 | P20: B>C
C21: Taxes | D21: -8330 | E21: -8303 | F21: -25474 | G21: =-G20*Assumption!G27 -> -19917.988 | H21: =-H20*Assumption!H27 -> -24440.715 | I21: =-I20*Assumption!I27 -> -30012.491 | J21: =-J20*Assumption!J27 -> -36814.065 | K21: =-K20*Assumption!K27 -> -45117.297 | P21: C>A
B22: x | C22: Net Income | D22: =D20+D21 -> 39098 | E22: =E20+E21 -> 62360 | F22: =F20+F21 -> 60458 | G22: =G20+G21 -> 74929.573 | H22: =H20+H21 -> 91943.642 | I22: =I20+I21 -> 112904.13 | J22: =J20+J21 -> 138491.01 | K22: =K20+K21 -> 169726.97
C24: Suplpement Info
C26: EBITDA | D26: =D18+D27 -> 57929 | E26: =E18+E27 -> 84878 | F26: =F18+F27 -> 101892 | G26: =G18+G27 -> 124834.86 | H26: =H18+H27 -> 154075.86 | I26: =I18+I27 -> 189332.86 | J26: =J18+J27 -> 231979.81 | K26: =K18+K27 -> 284811.8
C27: D&A | D27: ='D&A'!D14 -> 11178 | E27: ='D&A'!E14 -> 15498 | F27: ='D&A'!F14 -> 18616 | G27: ='D&A'!G14 -> 28477.516 | H27: ='D&A'!H14 -> 36337.67 | I27: ='D&A'!I14 -> 45469.59 | J27: ='D&A'!J14 -> 56194.536 | K27: ='D&A'!K14 -> 70021.31
B31: x | C31: Balance Sheet | D31: As of
C32: Assets | D32: =D4 -> 2023 | E32: =E4 -> 2024 | F32: =F4 -> 2025 | G32: =G4 -> 2026 | H32: =H4 -> 2027 | I32: =I4 -> 2028 | J32: =J4 -> 2029 | K32: =K4 -> 2030
C33: Current Assets
A34: imp | C34: Cash and cash equivalents | D34: 41862 | E34: 43889 | F34: 35873 | G34: =G114 -> 43269.074 | H34: =H114 -> 53665.344 | I34: =I114 -> 71933.738 | J34: =J114 -> 98187.871 | K34: =K114 -> 130558.43 | M34: Calc Later
A35: flat | C35: Marketable Securities / Short term Inv | D35: 23541 | E35: 33926 | F35: 45719 | G35: =F35 -> 45719 | H35: =G35 -> 45719 | I35: =H35 -> 45719 | J35: =I35 -> 45719 | K35: =J35 -> 45719 | M35: Same
A36: imp | C36: Account Receivable | D36: 16169 | E36: 16994 | F36: 19769 | G36: =WC!G9 -> 23496.475 | H36: =WC!H9 -> 28710.138 | I36: =WC!I9 -> 35080.666 | J36: =WC!J9 -> 42864.759 | K36: =WC!K9 -> 52376.075 | M36: WC
A37: imp | C37: Inventory
C38: Prepaid Exp | D38: 3793 | E38: 5236 | F38: 7361 | G38: =WC!G11 -> 7361 | H38: =WC!H11 -> 7361 | I38: =WC!I11 -> 7361 | J38: =WC!J11 -> 7361 | K38: =WC!K11 -> 7361 | M38: Same
C39: Total Current Assets | D39: =SUM(D34:D38) -> 85365 | E39: =SUM(E34:E38) -> 100045 | F39: =SUM(F34:F38) -> 108722 | G39: =SUM(G34:G38) -> 119845.55 | H39: =SUM(H34:H38) -> 135455.48 | I39: =SUM(I34:I38) -> 160094.4 | J39: =SUM(J34:J38) -> 194132.63 | K39: =SUM(K34:K38) -> 236014.51
G40: {=IFERROR(VLOOKUP(TRIM($C40),TRIM(WC!$C$5:$K$30),G$1,0),"")} | H40: {=IFERROR(VLOOKUP(TRIM($C40),TRIM(WC!$C$5:$K$30),H$1,0),"")} | I40: {=IFERROR(VLOOKUP(TRIM($C40),TRIM(WC!$C$5:$K$30),I$1,0),"")} | J40: {=IFERROR(VLOOKUP(TRIM($C40),TRIM(WC!$C$5:$K$30),J$1,0),"")} | K40: {=IFERROR(VLOOKUP(TRIM($C40),TRIM(WC!$C$5:$K$30),K$1,0),"")}
C41: Non-Current Assets | G41: {=IFERROR(VLOOKUP(TRIM($C41),TRIM(WC!$C$5:$K$30),G$1,0),"")} | H41: {=IFERROR(VLOOKUP(TRIM($C41),TRIM(WC!$C$5:$K$30),H$1,0),"")} | I41: {=IFERROR(VLOOKUP(TRIM($C41),TRIM(WC!$C$5:$K$30),I$1,0),"")} | J41: {=IFERROR(VLOOKUP(TRIM($C41),TRIM(WC!$C$5:$K$30),J$1,0),"")} | K41: {=IFERROR(VLOOKUP(TRIM($C41),TRIM(WC!$C$5:$K$30),K$1,0),"")}
C42: Non-marketable equity securities | D42: 6141 | E42: 6070 | F42: 27524 | G42: =F42 -> 27524 | H42: =G42 -> 27524 | I42: =H42 -> 27524 | J42: =I42 -> 27524 | K42: =J42 -> 27524 | M42: Same
A43: imp | C43: Property Plant and Equipment | D43: 96587 | E43: 121346 | F43: 176400 | G43: ='D&A'!G12 -> 233940.85 | H43: ='D&A'!H12 -> 302331.92 | I43: ='D&A'!I12 -> 384180.61 | J43: ='D&A'!J12 -> 482652.1 | K43: ='D&A'!K12 -> 601595.19 | M43: D&A
C44: Goodwill | D44: 20654 | E44: 20654 | F44: 24534 | G44: =F44 -> 24534 | H44: =G44 -> 24534 | I44: =H44 -> 24534 | J44: =I44 -> 24534 | K44: =J44 -> 24534 | M44: Same
A45: imp | C45: Intangible assets, net | D45: 788 | E45: 915 | F45: 3692 | G45: ='D&A'!G24 -> 2433 | H45: ='D&A'!H24 -> 1271 | I45: ='D&A'!I24 -> 500 | J45: ='D&A'!J24 -> 461 | K45: ='D&A'!K24 -> 434 | M45: D&A
...

Sheet DCF
P1: PGM | S1: EMM
P2: Cash Flows | Q2: Free Cash Flows | S2: Search EV/EBITDA Multiple of the industry * EBITDA
I3: Forecasting | P3: Terminal Growth Rate | Q3: Terminal Growth Rate (TGR)
C4: DCF | D4: For the Year Ended (FYE) | P4: Interest Rate | Q4: WACC - Weighted Avg Cost of Capital
D5: PV | F5: 2023 | G5: =F5+1 -> 2024 | H5: =G5+1 -> 2025 | I5: =H5+1 -> 2026 | J5: =I5+1 -> 2027 | K5: =J5+1 -> 2028 | L5: =K5+1 -> 2029 | M5: =L5+1 -> 2030 | P5: Terminal Value | Q5: Cash Flow*(1+TGR)/(WACC-TGR)
P6: PV of Terminal Value | Q6: FCFF/(1+WACC)^(FY-CY)
C7: EBIT | I7: ='Operating Model - IS, BS, CF'!G18 -> 96357.343 | J7: ='Operating Model - IS, BS, CF'!H18 -> 117738.19 | K7: ='Operating Model - IS, BS, CF'!I18 -> 143863.27 | L7: ='Operating Model - IS, BS, CF'!J18 -> 175785.27 | M7: ='Operating Model - IS, BS, CF'!K18 -> 214790.49
C8: Tax | I8: =Assumption!G27 -> 0.21 | J8: =Assumption!H27 -> 0.21 | K8: =Assumption!I27 -> 0.21 | L8: =Assumption!J27 -> 0.21 | M8: =Assumption!K27 -> 0.21 | P8: WACC Calc
C9: EBIT(1-Tax) | I9: =I7-I7*I8 -> 76122.301 | J9: =J7-J7*J8 -> 93013.174 | K9: =K7-K7*K8 -> 113651.98 | L9: =L7-L7*L8 -> 138870.37 | M9: =M7-M7*M8 -> 169684.49 | P9: Equity | Q9: =610*D32 -> 1543300
B10: - | C10: Capex | I10: ='Operating Model - IS, BS, CF'!G94 -> -84759.369 | J10: ='Operating Model - IS, BS, CF'!H94 -> -103566.73 | K10: ='Operating Model - IS, BS, CF'!I94 -> -126547.29 | L10: ='Operating Model - IS, BS, CF'!J94 -> -154627.02 | M10: ='Operating Model - IS, BS, CF'!K94 -> -188937.41 | P10: Debt | Q10: ='Operating Model - IS, BS, CF'!F55+'Operating Model - IS, BS, CF'!F56+'Operating Model - IS, BS, CF'!F57+'Operating Model - IS, BS, CF'!F62+'Operating Model - IS, BS, CF'!F63 -> 83897
B11: + | C11: D&A | I11: ='Operating Model - IS, BS, CF'!G27 -> 28477.516 | J11: ='Operating Model - IS, BS, CF'!H27 -> 36337.67 | K11: ='Operating Model - IS, BS, CF'!I27 -> 45469.59 | L11: ='Operating Model - IS, BS, CF'!J27 -> 56194.536 | M11: ='Operating Model - IS, BS, CF'!K27 -> 70021.31 | P11: Weight Equity | Q11: =Q9/SUM(Q9:Q10) -> 0.94844078
B12: - | C12: Change in WC | I12: ='Operating Model - IS, BS, CF'!G84 -> -2727.646 | J12: ='Operating Model - IS, BS, CF'!H84 -> -3018.3082 | K12: ='Operating Model - IS, BS, CF'!I84 -> -3688.0445 | L12: ='Operating Model - IS, BS, CF'!J84 -> -4506.3893 | M12: ='Operating Model - IS, BS, CF'!K84 -> -5506.3177 | P12: Weight Debt | Q12: =Q10/SUM(Q9:Q10) -> 0.051559215
C13: FCFF | I13: =SUM(I9:I12) -> 17112.802 | J13: =SUM(J9:J12) -> 22765.803 | K13: =SUM(K9:K12) -> 28886.245 | L13: =SUM(L9:L12) -> 35931.491 | M13: =SUM(M9:M12) -> 45262.073 | P13: Re (CAPM) | Q13: =Q23 -> 0.1076
C14: Growth % | J14: =J13/I13-1 -> 0.33033756 | K14: =K13/J13-1 -> 0.26884365 | L14: =L13/K13-1 -> 0.24389625 | M14: =M13/L13-1 -> 0.25967699 | P14: Rd | Q14: =Debt!P11 -> 0.048423729
D15: PGM | E15: EMM | P15: Tax | Q15: =Assumption!F27 -> 0.21
C16: Terminal Growth Rate | D16: 0.05 | P16: WACC | Q16: =Q11*Q13+Q12*Q14*(1-Q15) -> 0.10402461
C17: EV/EBITDA Multiple | E17: 12
C19: Terminal Value (2030) | D19: =M13*(1+D16)/(Q16-D16) -> 879694.9 | E19: =E17*'Operating Model - IS, BS, CF'!K26 -> 3417741.6 | P19: CAPM
P20: Risk Free Rt | Q20: 0.0456 | R20: ycharts
C21: PV of Cash Flows | D21: =SUM(I21:M21) -> 107425.79 | E21: =SUM(I21:M21) -> 107425.79 | I21: =I13/(1+$Q$16)^(I5-$H$5) -> 15500.381 | J21: =J13/(1+$Q$16)^(J5-$H$5) -> 18677.789 | K21: =K13/(1+$Q$16)^(K5-$H$5) -> 21466.182 | L21: =L13/(1+$Q$16)^(L5-$H$5) -> 24185.787 | M21: =M13/(1+$Q$16)^(M5-$H$5) -> 27595.652 | P21: Mkt Sentivity | Q21: 1.24 | R21: yahoofinance
C22: PV of Terminal Value | D22: =D19/(1+$Q$16)^($M$5-$H$5) -> 536337.66 | E22: =E19/(1+$Q$16)^($M$5-$H$5) -> 2083749.2 | P22: Mkt Risk Premium | Q22: 0.05 | R22: kroll
C23: Enterprise Value | D23: =SUM(D21:D22) -> 643763.45 | E23: =SUM(E21:E22) -> 2191175 | P23: CAPM | Q23: =Q20+Q21*Q22 -> 0.1076
B24: - | C24: Debt | D24: =-('Operating Model - IS, BS, CF'!F55+'Operating Model - IS, BS, CF'!F56+'Operating Model - IS, BS, CF'!F62) -> -58744 | E24: =D24 -> -58744
B25: - | C25: Preferred | D25: 0 | E25: =D25 -> 0
B26: - | C26: Minority | D26: 0 | E26: =D26 -> 0
B27: - | C27: Leases | D27: =-1*('Operating Model - IS, BS, CF'!F57+'Operating Model - IS, BS, CF'!F63) -> -25153 | E27: =D27 -> -25153
B28: + | C28: Cash | D28: =('Operating Model - IS, BS, CF'!F34+'Operating Model - IS, BS, CF'!F35) -> 81592 | E28: =D28 -> 81592
C30: Equity Value | D30: =SUM(D23:D28) -> 641458.45 | E30: =SUM(E23:E28) -> 2188870
C32: Share Outstanding | D32: =Assumption!F37 -> 2530 | E32: =D32 -> 2530
C34: Intrinsic Price Per Share | D34: =D30/D32 -> 253.54089 | E34: =E30/E32 -> 865.166
F36: What If Analysis
H37: WACC
G38: =D34 -> 253.54089 | H38: 0.08 | I38: 0.085 | J38: 0.088280551 | K38: 0.095
F39: Growth Rate | G39: 0.03 | H39: 295.56492 | I39: 266.86381 | J39: 250.72508 | K39: 222.79064
G40: 0.04 | H40: 361.31388 | I40: 319.02167 | J40: 296.05183 | K40: 257.59882
G41: 0.05 | H41: 470.89548 | I41: 400.98402 | J41: 365.05993 | K41: 307.87731
G42: 0.06 | H42: 690.05869 | I42: 548.51626 | J42: 482.87053 | K42: 386.88637
H44: WACC
G45: =E34 -> 865.166 | H45: 0.08 | I45: 0.085 | J45: 0.088280551 | K45: 0.095
F46: Exit Multiple | G46: 8 | H46: 657.67168 | I46: 642.98491 | J46: 633.56528 | K46: 614.79004
...

Sheet Revenue
B3: X | C3: Revenue | H3: For the Year Ended (FYE)
D4: Q1 2023 | E4: Q2 2023 | F4: Q3 2023 | G4: Q4 2023 | H4: 2023 | I4: Q1 2024 | J4: Q2 2024 | K4: Q3 2024 | L4: Q4 2024 | M4: =H4+1 -> 2024 | N4: Q1 2025 | O4: Q2 2025 | P4: Q3 2025 | Q4: Q4 2025 | R4: =M4+1 -> 2025 | S4: =R4+1 -> 2026 | T4: =S4+1 -> 2027 | U4: =T4+1 -> 2028 | V4: =U4+1 -> 2029 | W4: =V4+1 -> 2030
B6: million | C6: DAP | D6: 3020 | E6: 3070 | F6: 3140 | G6: 3190 | H6: =AVERAGE(D6:G6) -> 3105 | I6: 3240 | J6: 3270 | K6: 3290 | L6: 3350 | M6: =AVERAGE(I6:L6) -> 3287.5 | N6: 3430 | O6: 3480 | P6: 3540 | Q6: 3580 | R6: =AVERAGE(N6:Q6) -> 3507.5 | S6: =R6+Assumption!G11*R6 -> 3727.9399 | T6: =S6+Assumption!H11*S6 -> 3962.2341 | U6: =T6+Assumption!I11*T6 -> 4211.2532 | V6: =U6+Assumption!J11*U6 -> 4475.9227 | W6: =V6+Assumption!K11*V6 -> 4757.2262 | Z6: No. of users (DAP) | AA6: 3.58 | AB6: Billion | AC6: =AA6/AA7 -> 0.4475
C7: % Growth | M7: =M6/H6-1 -> 0.058776167 | R7: =R6/M6-1 -> 0.066920152 | S7: =Assumption!G11 -> 0.06284816 | T7: =Assumption!H11 -> 0.06284816 | U7: =Assumption!I11 -> 0.06284816 | V7: =Assumption!J11 -> 0.06284816 | W7: =Assumption!K11 -> 0.06284816 | Z7: World Population | AA7: 8 | AB7: Billion
Z8: Avg Revenue Per Person (ARPU) | AA8: =16.56*4 -> 66.24
B9: absolute | C9: ARPP | D9: 9.47 | E9: 10.42 | F9: 10.93 | G9: 12.33 | H9: =SUM(D9:G9) -> 43.15 | I9: 11.2 | J9: 11.89 | K9: 12.29 | L9: 14.25 | M9: =SUM(I9:L9) -> 49.63 | N9: 12.36 | O9: 13.65 | P9: 14.46 | Q9: 16.56 | R9: =SUM(N9:Q9) -> 57.03 | S9: =R9+Assumption!G16*R9 -> 65.563889 | T9: =S9+Assumption!H16*S9 -> 75.374776 | U9: =T9+Assumption!I16*T9 -> 86.653752 | V9: =U9+Assumption!J16*U9 -> 99.620497 | W9: =V9+Assumption!K16*V9 -> 114.52757
C10: % Growth | M10: =M9/H9-1 -> 0.15017381 | R10: =R9/M9-1 -> 0.14910336 | S10: =Assumption!G16 -> 0.14963859 | T10: =Assumption!H16 -> 0.14963859 | U10: =Assumption!I16 -> 0.14963859 | V10: =Assumption!J16 -> 0.14963859 | W10: =Assumption!K16 -> 0.14963859 | Z10: Revenue | AA10: =AA8*AA6 -> 237.1392 | AB10: US Billion $
C12: Revenue | D12: =D9*D6 -> 28599.4 | E12: =E9*E6 -> 31989.4 | F12: =F9*F6 -> 34320.2 | G12: =G9*G6 -> 39332.7 | H12: =H9*H6 -> 133980.75 | I12: =I9*I6 -> 36288 | J12: =J9*J6 -> 38880.3 | K12: =K9*K6 -> 40434.1 | ... R12: =R9*R6 -> 200032.73 | S12: =S6*S9 -> 244418.24 | T12: =T6*T9 -> 298652.51 | U12: =U6*U9 -> 364920.89 | V12: =V6*V9 -> 445893.64 | W12: =W6*W9 -> 544833.55
C13: % Growth | M13: =M12/H12-1 -> 0.21777662 | R13: =R12/M12-1 -> 0.22600154 | S13: =S12/R12-1 -> 0.22189126 | T13: =T12/S12-1 -> 0.22189126 | U13: =U12/T12-1 -> 0.22189126 | V13: =V12/U12-1 -> 0.22189126 | W13: =W12/V12-1 -> 0.22189126

Sheet D&A
B3: X | C3: Dep and Ammort | D3: For the Year Ended (FYE)
D4: 2023 | E4: =D4+1 -> 2024 | F4: =E4+1 -> 2025 | G4: =F4+1 -> 2026 | H4: =G4+1 -> 2027 | I4: =H4+1 -> 2028 | J4: =I4+1 -> 2029 | K4: =J4+1 -> 2030
C5: Revenue | D5: ='Operating Model - IS, BS, CF'!D5 -> 134902 | E5: ='Operating Model - IS, BS, CF'!E5 -> 164501 | F5: ='Operating Model - IS, BS, CF'!F5 -> 200966 | G5: ='Operating Model - IS, BS, CF'!G5 -> 244418.24 | H5: ='Operating Model - IS, BS, CF'!H5 -> 298652.51 | I5: ='Operating Model - IS, BS, CF'!I5 -> 364920.89 | J5: ='Operating Model - IS, BS, CF'!J5 -> 445893.64 | K5: ='Operating Model - IS, BS, CF'!K5 -> 544833.55
C6: CapEx | D6: ='Operating Model - IS, BS, CF'!D94 -> -27045 | E6: ='Operating Model - IS, BS, CF'!E94 -> -37256 | F6: ='Operating Model - IS, BS, CF'!F94 -> -69691 | G6: =Assumption!G30*G5 -> -84759.369 | H6: =Assumption!H30*H5 -> -103566.73 | I6: =Assumption!I30*I5 -> -126547.29 | J6: =Assumption!J30*J5 -> -154627.02 | K6: =Assumption!K30*K5 -> -188937.41
C7: % of sales | D7: =D6/D5 -> -0.20047887 | E7: =E6/E5 -> -0.22647887 | F7: =F6/F5 -> -0.34678005
C9: PPE opening | E9: =D12 -> 96587 | F9: =E12 -> 121346 | G9: =F12 -> 176400 | H9: =G12 -> 233940.85 | I9: =H12 -> 302331.92 | J9: =I12 -> 384180.61 | K9: =J12 -> 482652.1
B10: + | C10: cap ex | D10: =-D6 -> 27045 | E10: =-E6 -> 37256 | F10: =-F6 -> 69691 | G10: =-G6 -> 84759.369 | H10: =-H6 -> 103566.73 | I10: =-I6 -> 126547.29 | J10: =-J6 -> 154627.02 | K10: =-K6 -> 188937.41
B11: - | C11: depn | G11: =-G16 -> -27218.516 | H11: =-H16 -> -35175.67 | I11: =-I16 -> -44698.59 | J11: =-J16 -> -56155.536 | K11: =-K16 -> -69994.31
C12: ppe closing | D12: ='Operating Model - IS, BS, CF'!D43 -> 96587 | E12: ='Operating Model - IS, BS, CF'!E43 -> 121346 | F12: ='Operating Model - IS, BS, CF'!F43 -> 176400 | G12: =SUM(G9:G11) -> 233940.85 | H12: =SUM(H9:H11) -> 302331.92 | I12: =SUM(I9:I11) -> 384180.61 | J12: =SUM(J9:J11) -> 482652.1 | K12: =SUM(K9:K11) -> 601595.19
C14: d&a | D14: ='Operating Model - IS, BS, CF'!D83 -> 11178 | E14: ='Operating Model - IS, BS, CF'!E83 -> 15498 | F14: ='Operating Model - IS, BS, CF'!F83 -> 18616 | G14: =G16+Assumption!G32 -> 28477.516 | H14: =H16+Assumption!H32 -> 36337.67 | I14: =I16+Assumption!I32 -> 45469.59 | J14: =J16+Assumption!J32 -> 56194.536 | K14: =K16+Assumption!K32 -> 70021.31
C16: dep | D16: =D14-Assumption!D32 -> 11017 | E16: =E14-Assumption!E32 -> 15287 | F16: =F14-Assumption!F32 -> 18001 | G16: =SUM(G9:G10)*Assumption!G31 -> 27218.516 | H16: =SUM(H9:H10)*Assumption!H31 -> 35175.67 | I16: =SUM(I9:I10)*Assumption!I31 -> 44698.59 | J16: =SUM(J9:J10)*Assumption!J31 -> 56155.536 | K16: =SUM(K9:K10)*Assumption!K31 -> 69994.31
C17: % of ppe | E17: =E16/SUM(E9:E10) -> 0.11421591 | F17: =F16/SUM(F9:F10) -> 0.09422782
C21: Intangible assets opening | E21: =D24 -> 788 | F21: =E24 -> 915 | G21: =F24 -> 3692 | H21: =G24 -> 2433 | I21: =H24 -> 1271 | J21: =I24 -> 500 | K21: =J24 -> 461
C22: Purchase of Intangible | E22: =-'Operating Model - IS, BS, CF'!E95 -> 270 | F22: =-'Operating Model - IS, BS, CF'!F95 -> 4231
C23: Ammortization | D23: =Assumption!D32 -> 161 | E23: =Assumption!E32 -> 211 | F23: =Assumption!F32 -> 615 | G23: =-Assumption!G32 -> -1259 | H23: =-Assumption!H32 -> -1162 | I23: =-Assumption!I32 -> -771 | J23: =-Assumption!J32 -> -39 | K23: =-Assumption!K32 -> -27
C24: Intangible assets closing | D24: ='Operating Model - IS, BS, CF'!D45 -> 788 | E24: ='Operating Model - IS, BS, CF'!E45 -> 915 | F24: ='Operating Model - IS, BS, CF'!F45 -> 3692 | G24: =SUM(G21:G23) -> 2433 | H24: =SUM(H21:H23) -> 1271 | I24: =SUM(I21:I23) -> 500 | J24: =SUM(J21:J23) -> 461 | K24: =SUM(K21:K23) -> 434
C26: Amortization | D26: =Assumption!D32 -> 161 | E26: =Assumption!E32 -> 211 | F26: =Assumption!F32 -> 615 | G26: =SUM(G21:G21)*G27 -> 588.76913 | H26: =SUM(H21:H21)*H27 -> 387.99439 | I26: =SUM(I21:I21)*I27 -> 202.6884 | J26: =SUM(J21:J21)*J27 -> 79.735798 | K26: =SUM(K21:K21)*K27 -> 73.516406
C27: %of Intangibles | E27: =E26/SUM(E21:E22) -> 0.19943289 | F27: =F26/SUM(F21:F22) -> 0.1195103 | G27: =AVERAGE($E$27:$F$27) -> 0.1594716 | H27: =AVERAGE($E$27:$F$27) -> 0.1594716 | I27: =AVERAGE($E$27:$F$27) -> 0.1594716 | J27: =AVERAGE($E$27:$F$27) -> 0.1594716 | K27: =AVERAGE($E$27:$F$27) -> 0.1594716

Sheet WC
C2: 1 | D2: 2 | E2: 3 | F2: 4 | G2: 5 | H2: 6 | I2: 7 | J2: 8 | K2: 9
B3: X | C3: Working Capital | D3: For the Year Ended (FYE)
D4: 2023 | E4: =D4+1 -> 2024 | F4: =E4+1 -> 2025 | G4: =F4+1 -> 2026 | H4: =G4+1 -> 2027 | I4: =H4+1 -> 2028 | J4: =I4+1 -> 2029 | K4: =J4+1 -> 2030
C5: Revenue | D5: ='Operating Model - IS, BS, CF'!D5 -> 134902 | E5: ='Operating Model - IS, BS, CF'!E5 -> 164501 | F5: ='Operating Model - IS, BS, CF'!F5 -> 200966 | G5: ='Operating Model - IS, BS, CF'!G5 -> 244418.24 | H5: ='Operating Model - IS, BS, CF'!H5 -> 298652.51 | I5: ='Operating Model - IS, BS, CF'!I5 -> 364920.89 | J5: ='Operating Model - IS, BS, CF'!J5 -> 445893.64 | K5: ='Operating Model - IS, BS, CF'!K5 -> 544833.55
C6: Cogs | D6: ='Operating Model - IS, BS, CF'!D7 -> -25959 | E6: ='Operating Model - IS, BS, CF'!E7 -> -30161 | F6: ='Operating Model - IS, BS, CF'!F7 -> -36175 | G6: ='Operating Model - IS, BS, CF'!G7 -> -45281.133 | H6: ='Operating Model - IS, BS, CF'!H7 -> -55328.621 | I6: ='Operating Model - IS, BS, CF'!I7 -> -67605.558 | J6: ='Operating Model - IS, BS, CF'!J7 -> -82606.64 | K6: ='Operating Model - IS, BS, CF'!K7 -> -100936.33
C8: Non-Cash current assets
C9: Account Receivable | D9: =VLOOKUP($C9,'Operating Model - IS, BS, CF'!$C$32:$F$78,$D$2,0) -> 16169 | E9: =VLOOKUP($C9,'Operating Model - IS, BS, CF'!$C$32:$F$78,$E$2,0) -> 16994 | F9: =VLOOKUP($C9,'Operating Model - IS, BS, CF'!$C$32:$F$78,$F$2,0) -> 19769 | G9: =(G5/G21) -> 23496.475 | H9: =(H5/H21) -> 28710.138 | I9: =(I5/I21) -> 35080.666 | J9: =(J5/J21) -> 42864.759 | K9: =(K5/K21) -> 52376.075 | O9: RT = Revenue/Avg AR
C10: Inventory | D10: =VLOOKUP($C10,'Operating Model - IS, BS, CF'!$C$32:$F$78,$D$2,0) -> 0 | E10: =VLOOKUP($C10,'Operating Model - IS, BS, CF'!$C$32:$F$78,$E$2,0) -> 0 | F10: =VLOOKUP($C10,'Operating Model - IS, BS, CF'!$C$32:$F$78,$F$2,0) -> 0 | G10: =Assumption!G42 -> 0 | H10: =Assumption!H42 -> 0 | I10: =Assumption!I42 -> 0 | J10: =Assumption!J42 -> 0 | K10: =Assumption!K42 -> 0
C11: Prepaid Exp | D11: =VLOOKUP($C11,'Operating Model - IS, BS, CF'!$C$32:$F$78,$D$2,0) -> 3793 | E11: =VLOOKUP($C11,'Operating Model - IS, BS, CF'!$C$32:$F$78,$E$2,0) -> 5236 | F11: =VLOOKUP($C11,'Operating Model - IS, BS, CF'!$C$32:$F$78,$F$2,0) -> 7361 | G11: =Assumption!G43 -> 7361 | H11: =Assumption!H43 -> 7361 | I11: =Assumption!I43 -> 7361 | J11: =Assumption!J43 -> 7361 | K11: =Assumption!K43 -> 7361 | O11: AVG AR = (AR cur year + AR past year)/2
C12: Total Non-Cash Current Assets | D12: =SUM(D9:D11) -> 19962 | E12: =SUM(E9:E11) -> 22230 | F12: =SUM(F9:F11) -> 27130 | G12: =SUM(G9:G11) -> 30857.475 | H12: =SUM(H9:H11) -> 36071.138 | I12: =SUM(I9:I11) -> 42441.666 | J12: =SUM(J9:J11) -> 50225.759 | K12: =SUM(K9:K11) -> 59737.075
C13: Non-Debt current Liabilities | O13: DSO = 365/ RT
C14: Account Payable | D14: =VLOOKUP($C14,'Operating Model - IS, BS, CF'!$C$32:$F$78,$D$2,0) -> 4849 | E14: =VLOOKUP($C14,'Operating Model - IS, BS, CF'!$C$32:$F$78,$E$2,0) -> 7687 | F14: =VLOOKUP($C14,'Operating Model - IS, BS, CF'!$C$32:$F$78,$F$2,0) -> 8894 | G14: =(-G6/G24) -> 9893.8291 | H14: =(-H6/H24) -> 12089.183 | I14: =(-I6/I24) -> 14771.667 | J14: =(-J6/J24) -> 18049.371 | K14: =(-K6/K24) -> 22054.369 | O14: RT = 365/DSO
C15: Accrued expenses and other current liabilities | D15: =VLOOKUP($C15,'Operating Model - IS, BS, CF'!$C$32:$F$78,$D$2,0) -> 25488 | E15: =VLOOKUP($C15,'Operating Model - IS, BS, CF'!$C$32:$F$78,$E$2,0) -> 23967 | F15: =VLOOKUP($C15,'Operating Model - IS, BS, CF'!$C$32:$F$78,$F$2,0) -> 30729 | G15: =Assumption!G44 -> 30729 | H15: =Assumption!H44 -> 30729 | I15: =Assumption!I44 -> 30729 | J15: =Assumption!J44 -> 30729 | K15: =Assumption!K44 -> 30729 | O15: REV/AVG AR = 365/DSO
C16: Total Non-Debt Current Liabilities | D16: =SUM(D14:D15) -> 30337 | E16: =SUM(E14:E15) -> 31654 | F16: =SUM(F14:F15) -> 39623 | G16: =SUM(G14:G15) -> 40622.829 | H16: =SUM(H14:H15) -> 42818.183 | I16: =SUM(I14:I15) -> 45500.667 | J16: =SUM(J14:J15) -> 48778.371 | K16: =SUM(K14:K15) -> 52783.369 | O16: AVG AR = REV*DSO/365
C18: Working Capital | D18: =D12-D16 -> -10375 | E18: =E12-E16 -> -9424 | F18: =F12-F16 -> -12493 | G18: =G12-G16 -> -9765.354 | H18: =H12-H16 -> -6747.0457 | I18: =I12-I16 -> -3059.0013 | J18: =J12-J16 -> 1447.388 | K18: =K12-K16 -> 6953.7057 | O18: (AR cur year + AR past year)/2 = REV*DSO/365
C19: Change in Working Capital | G19: =G18-F18 -> 2727.646 | H19: =H18-G18 -> 3018.3082 | I19: =I18-H18 -> 3688.0445 | J19: =J18-I18 -> 4506.3893 | K19: =K18-J18 -> 5506.3177
O20: AR cur year = (2* Rev * DSO /365) - Rev Past Year
C21: Receivable Turnover | E21: =E5/AVERAGE(D9:E9) -> 9.9207551 | F21: =F5/AVERAGE(E9:F9) -> 10.933058 | G21: =Assumption!G45/Assumption!G46 -> 10.402336 | H21: =Assumption!H45/Assumption!H46 -> 10.402336 | I21: =Assumption!I45/Assumption!I46 -> 10.402336 | J21: =Assumption!J45/Assumption!J46 -> 10.402336 | K21: =Assumption!K45/Assumption!K46 -> 10.402336
C22: Inventory Turnover | E22: =IFERROR(E6/AVERAGE(D10:E10),"n.a.") -> n.a. | F22: =IFERROR(F6/AVERAGE(E10:F10),"n.a.") -> n.a. | G22: n.a. | H22: n.a. | I22: n.a. | J22: n.a. | K22: n.a.
C24: Payble Turnover | E24: =-E6/AVERAGE(D14:E14) -> 4.8119017 | F24: =-F6/AVERAGE(E14:F14) -> 4.363428 | G24: =Assumption!G45/Assumption!G48 -> 4.5767046 | H24: =Assumption!H45/Assumption!H48 -> 4.5767046 | I24: =Assumption!I45/Assumption!I48 -> 4.5767046 | J24: =Assumption!J45/Assumption!J48 -> 4.5767046 | K24: =Assumption!K45/Assumption!K48 -> 4.5767046

Sheet Equity
B3: X | C3: Equity | D3: For the Year Ended (FYE)
D4: 2023 | E4: =D4+1 -> 2024 | F4: =E4+1 -> 2025 | G4: =F4+1 -> 2026 | H4: =G4+1 -> 2027 | I4: =H4+1 -> 2028 | J4: =I4+1 -> 2029 | K4: =J4+1 -> 2030
C5: Equity Capital - Opening | E5: =D8 -> 71098 | F5: =E8 -> 80131 | G5: =F8 -> 96064 | H5: =G8 -> 96064 | I5: =H8 -> 96064 | J5: =I8 -> 96064 | K5: =J8 -> 96064
B6: + | C6: Issuance | G6: =Assumption!G38 -> 0 | H6: =Assumption!H38 -> 0 | I6: =Assumption!I38 -> 0 | J6: =Assumption!J38 -> 0 | K6: =Assumption!K38 -> 0 | M6: Maybe company would raise capital from equity but fn we assume zero.
B7: - | C7: Repurchaseor Buyback | G7: =Assumption!G39 -> 0 | H7: =Assumption!H39 -> 0 | I7: =Assumption!I39 -> 0 | J7: =Assumption!J39 -> 0 | K7: =Assumption!K39 -> 0
C8: Equity Capital - Closing | D8: ='Operating Model - IS, BS, CF'!D72 -> 71098 | E8: ='Operating Model - IS, BS, CF'!E72 -> 80131 | F8: ='Operating Model - IS, BS, CF'!F72 -> 96064 | G8: =SUM(G5:G7) -> 96064 | H8: =SUM(H5:H7) -> 96064 | I8: =SUM(I5:I7) -> 96064 | J8: =SUM(J5:J7) -> 96064 | K8: =SUM(K5:K7) -> 96064
C10: Retained Earnings - Opening | E10: =D13 -> 82070 | F10: =E13 -> 102506 | G10: =F13 -> 121179 | H10: =G13 -> 190795.57 | I10: =H13 -> 277426.21 | J10: =I13 -> 385017.35 | K10: =J13 -> 518195.36
B11: + | C11: Net Income | D11: ='Operating Model - IS, BS, CF'!D22 -> 39098 | E11: ='Operating Model - IS, BS, CF'!E22 -> 62360 | F11: ='Operating Model - IS, BS, CF'!F22 -> 60458 | G11: ='Operating Model - IS, BS, CF'!G22 -> 74929.573 | H11: ='Operating Model - IS, BS, CF'!H22 -> 91943.642 | I11: ='Operating Model - IS, BS, CF'!I22 -> 112904.13 | J11: ='Operating Model - IS, BS, CF'!J22 -> 138491.01 | K11: ='Operating Model - IS, BS, CF'!K22 -> 169726.97
B12: - | C12: Dividend | E12: =-Assumption!E36*Assumption!E37 -> -5068 | F12: =-Assumption!F36*Assumption!F37 -> -5313 | G12: =-Assumption!G36*Assumption!G37 -> -5313 | H12: =-Assumption!H36*Assumption!H37 -> -5313 | I12: =-Assumption!I36*Assumption!I37 -> -5313 | J12: =-Assumption!J36*Assumption!J37 -> -5313 | K12: =-Assumption!K36*Assumption!K37 -> -5313
C13: Retained Earnings - Closing | D13: ='Operating Model - IS, BS, CF'!D73 -> 82070 | E13: ='Operating Model - IS, BS, CF'!E73 -> 102506 | F13: ='Operating Model - IS, BS, CF'!F73 -> 121179 | G13: =SUM(G10:G12) -> 190795.57 | H13: =SUM(H10:H12) -> 277426.21 | I13: =SUM(I10:I12) -> 385017.35 | J13: =SUM(J10:J12) -> 518195.36 | K13: =SUM(K10:K12) -> 682609.33

Sheet Debt
B3: X | C3: Debt | D3: For the Year Ended (FYE)
D4: 2023 | E4: =D4+1 -> 2024 | F4: =E4+1 -> 2025 | G4: =F4+1 -> 2026 | H4: =G4+1 -> 2027 | I4: =H4+1 -> 2028 | J4: =I4+1 -> 2029 | K4: =J4+1 -> 2030 | M4: Long Term Debt Repayment Int Rate
C6: LT Debt opening | E6: =D9 -> 18385 | F6: =E9 -> 28826 | G6: =F9 -> 58744 | H6: =G9 -> 58744 | I6: =H9 -> 55994 | J6: =I9 -> 54494 | K6: =J9 -> 53494 | M6: Note Header | N6: Maturity | O6: Stated Interest Rate | P6: Avg of Stated Int Rate | Q6: December 31, 2025 | R6: Int Amount
B7: + | C7: Isssuance | G7: =Assumption!G51 -> 0 | H7: =Assumption!H51 -> 0 | I7: =Assumption!I51 -> 0 | J7: =Assumption!J51 -> 0 | K7: =Assumption!K51 -> 0 | M7: August 2022 Notes | N7: 2027 - 2062 | O7: 3.50% - 4.65% | P7: 0.04075 | Q7: 10000 | R7: =Q7*P7 -> 407.5
B8: - | C8: Repayment | G8: =Assumption!G52 -> 0 | H8: =Assumption!H52 -> -2750 | I8: =Assumption!I52 -> -1500 | J8: =Assumption!J52 -> -1000 | K8: =Assumption!K52 -> -5000 | M8: May 2023 Notes | N8: 2028 - 2063 | O8: 4.60% - 5.75% | P8: 0.05175 | Q8: 8500 | R8: =Q8*P8 -> 439.875
C9: LT Debt Closing | D9: ='Operating Model - IS, BS, CF'!D62 -> 18385 | E9: ='Operating Model - IS, BS, CF'!E62 -> 28826 | F9: ='Operating Model - IS, BS, CF'!F62 -> 58744 | G9: =SUM(G6:G8) -> 58744 | H9: =SUM(H6:H8) -> 55994 | I9: =SUM(I6:I8) -> 54494 | J9: =SUM(J6:J8) -> 53494 | K9: =SUM(K6:K8) -> 48494 | M9: August 2024 Notes | N9: 2029 - 2064 | O9: 4.30% - 5.55% | P9: 0.04925 | Q9: 10500 | R9: =Q9*P9 -> 517.125
M10: November 2025 Notes | N10: 2030 - 2065 | O10: 4.20% - 5.75% | P10: 0.04975 | Q10: 30000 | R10: =Q10*P10 -> 1492.5
C11: ST Debt opening | E11: =D14 -> 0 | F11: =E14 -> 0 | G11: =F14 -> 0 | H11: =G14 -> 0 | I11: =H14 -> 0 | J11: =I14 -> 0 | K11: =J14 -> 0 | M11: Avg Interest Rate | P11: =Assumption!G67 -> 0.048423729 | Q11: =SUM(Q7:Q10) -> 59000 | R11: =SUM(R7:R10) -> 2857
B12: + | C12: Isssuance | G12: =Assumption!G55 -> 0 | H12: =Assumption!H55 -> 0 | I12: =Assumption!I55 -> 0 | J12: =Assumption!J55 -> 0 | K12: =Assumption!K55 -> 0
B13: - | C13: Repayment | G13: =Assumption!G56 -> 0 | H13: =Assumption!H56 -> 0 | I13: =Assumption!I56 -> 0 | J13: =Assumption!J56 -> 0 | K13: =Assumption!K56 -> 0 | M13: Expected Interest Rate which company will charge | N13: =Assumption!G66 -> 0.015
C14: ST Debt Closing | D14: 0 | E14: 0 | F14: 0 | G14: =SUM(G11:G13) -> 0 | H14: =SUM(H11:H13) -> 0 | I14: =SUM(I11:I13) -> 0 | J14: =SUM(J11:J13) -> 0 | K14: =SUM(K11:K13) -> 0
C16: Current Leases Opening | E16: =D19 -> 1623 | F16: =E19 -> 1942 | G16: =F19 -> 2213 | H16: =G19 -> 0 | I16: =H19 -> 0 | J16: =I19 -> 0 | K16: =J19 -> 0
B17: + | C17: Isssuance | G17: =Assumption!G63 -> 0 | H17: =Assumption!H63 -> 0 | I17: =Assumption!I63 -> 0 | J17: =Assumption!J63 -> 0 | K17: =Assumption!K63 -> 0
B18: - | C18: Repayment | G18: =Assumption!G64 -> -2213 | H18: =Assumption!H64 -> 0 | I18: =Assumption!I64 -> 0 | J18: =Assumption!J64 -> 0 | K18: =Assumption!K64 -> 0
C19: Current Leases Closing | D19: ='Operating Model - IS, BS, CF'!D57 -> 1623 | E19: ='Operating Model - IS, BS, CF'!E57 -> 1942 | F19: ='Operating Model - IS, BS, CF'!F57 -> 2213 | G19: =SUM(G16:G18) -> 0 | H19: =SUM(H16:H18) -> 0 | I19: =SUM(I16:I18) -> 0 | J19: =SUM(J16:J18) -> 0 | K19: =SUM(K16:K18) -> 0
C21: Non-Current Leases Opening | E21: =D24 -> 17226 | F21: =E24 -> 18292 | G21: =F24 -> 22940 | H21: =G24 -> 21942 | I21: =H24 -> 18705 | J21: =I24 -> 15648 | K21: =J24 -> 12663
B22: + | C22: Isssuance | G22: =Assumption!G59 -> 0 | H22: =Assumption!H59 -> 0 | I22: =Assumption!I59 -> 0 | J22: =Assumption!J59 -> 0 | K22: =Assumption!K59 -> 0
B23: - | C23: Repayment | G23: =Assumption!G60 -> -998 | H23: =Assumption!H60 -> -3237 | I23: =Assumption!I60 -> -3057 | J23: =Assumption!J60 -> -2985 | K23: =Assumption!K60 -> -2621
C24: Non-Current Leases Closing | D24: ='Operating Model - IS, BS, CF'!D63 -> 17226 | E24: ='Operating Model - IS, BS, CF'!E63 -> 18292 | F24: ='Operating Model - IS, BS, CF'!F63 -> 22940 | G24: =SUM(G21:G23) -> 21942 | H24: =SUM(H21:H23) -> 18705 | I24: =SUM(I21:I23) -> 15648 | J24: =SUM(J21:J23) -> 12663 | K24: =SUM(K21:K23) -> 10042
C26: Interest Expense | G26: =G6*Assumption!$G$67 -> 2844.6035 | H26: =H6*Assumption!$G$67 -> 2844.6035 | I26: =I6*Assumption!$G$67 -> 2711.4383 | J26: =J6*Assumption!$G$67 -> 2638.8027 | K26: =K6*Assumption!$G$67 -> 2590.3789
C27: Interest Income | G27: =SUM('Operating Model - IS, BS, CF'!G34:G35)*Assumption!$G$66 -> 1334.8211 | H27: =SUM('Operating Model - IS, BS, CF'!H34:H35)*Assumption!$G$66 -> 1490.7652 | I27: =SUM('Operating Model - IS, BS, CF'!I34:I35)*Assumption!$G$66 -> 1764.7911 | J27: =SUM('Operating Model - IS, BS, CF'!J34:J35)*Assumption!$G$66 -> 2158.6031 | K27: =SUM('Operating Model - IS, BS, CF'!K34:K35)*Assumption!$G$66 -> 2644.1615
C29: Net Interest (Exp)/Income | G29: =G27-G26 -> -1509.7824 | H29: =H27-H26 -> -1353.8384 | I29: =I27-I26 -> -946.64721 | J29: =J27-J26 -> -480.19961 | K29: =K27-K26 -> 53.782535
C32: RCF
C33: Beginning cash balance | G33: ='Operating Model - IS, BS, CF'!G112 -> 35873 | H33: ='Operating Model - IS, BS, CF'!H112 -> 43269.074 | I33: ='Operating Model - IS, BS, CF'!I112 -> 53665.344 | J33: ='Operating Model - IS, BS, CF'!J112 -> 71933.738 | K33: ='Operating Model - IS, BS, CF'!K112 -> 98187.871
C34: Cash Flow from Operations (CFO) | G34: ='Operating Model - IS, BS, CF'!G91 -> 100679.44 | H34: ='Operating Model - IS, BS, CF'!H91 -> 125263 | I34: ='Operating Model - IS, BS, CF'!I91 -> 154685.68 | J34: ='Operating Model - IS, BS, CF'!J91 -> 190179.16 | K34: ='Operating Model - IS, BS, CF'!K91 -> 234241.97
C35: Cash Flow from Investing (CFI) | G35: ='Operating Model - IS, BS, CF'!G96 -> -84759.369 | H35: ='Operating Model - IS, BS, CF'!H96 -> -103566.73 | I35: ='Operating Model - IS, BS, CF'!I96 -> -126547.29 | J35: ='Operating Model - IS, BS, CF'!J96 -> -154627.02 | K35: ='Operating Model - IS, BS, CF'!K96 -> -188937.41
C36: Equity Issuance / Equity Raise | G36: ='Operating Model - IS, BS, CF'!G98 -> 0 | H36: ='Operating Model - IS, BS, CF'!H98 -> 0 | I36: ='Operating Model - IS, BS, CF'!I98 -> 0 | J36: ='Operating Model - IS, BS, CF'!J98 -> 0 | K36: ='Operating Model - IS, BS, CF'!K98 -> 0
C37: Equity Repurchase | G37: ='Operating Model - IS, BS, CF'!G99 -> 0 | H37: ='Operating Model - IS, BS, CF'!H99 -> 0 | I37: ='Operating Model - IS, BS, CF'!I99 -> 0 | J37: ='Operating Model - IS, BS, CF'!J99 -> 0 | K37: ='Operating Model - IS, BS, CF'!K99 -> 0
C38: Dividend Paid | G38: ='Operating Model - IS, BS, CF'!G100 -> -5313 | H38: ='Operating Model - IS, BS, CF'!H100 -> -5313 | I38: ='Operating Model - IS, BS, CF'!I100 -> -5313 | J38: ='Operating Model - IS, BS, CF'!J100 -> -5313 | K38: ='Operating Model - IS, BS, CF'!K100 -> -5313
C39: Debt Issuance | G39: ='Operating Model - IS, BS, CF'!G101 -> 0 | H39: ='Operating Model - IS, BS, CF'!H101 -> 0 | I39: ='Operating Model - IS, BS, CF'!I101 -> 0 | J39: ='Operating Model - IS, BS, CF'!J101 -> 0 | K39: ='Operating Model - IS, BS, CF'!K101 -> 0
C40: Debt Repayment | G40: ='Operating Model - IS, BS, CF'!G102 -> 0 | H40: ='Operating Model - IS, BS, CF'!H102 -> -2750 | I40: ='Operating Model - IS, BS, CF'!I102 -> -1500 | J40: ='Operating Model - IS, BS, CF'!J102 -> -1000 | K40: ='Operating Model - IS, BS, CF'!K102 -> -5000
C41: Current Op Lease Issuance | G41: ='Operating Model - IS, BS, CF'!G103 -> 0 | H41: ='Operating Model - IS, BS, CF'!H103 -> 0 | I41: ='Operating Model - IS, BS, CF'!I103 -> 0 | J41: ='Operating Model - IS, BS, CF'!J103 -> 0 | K41: ='Operating Model - IS, BS, CF'!K103 -> 0
C42: Current Op Lease Repayment | G42: ='Operating Model - IS, BS, CF'!G104 -> -2213 | H42: ='Operating Model - IS, BS, CF'!H104 -> 0 | I42: ='Operating Model - IS, BS, CF'!I104 -> 0 | J42: ='Operating Model - IS, BS, CF'!J104 -> 0 | K42: ='Operating Model - IS, BS, CF'!K104 -> 0
C43: Non-Current Op Lease Issuance | G43: ='Operating Model - IS, BS, CF'!G105 -> 0 | H43: ='Operating Model - IS, BS, CF'!H105 -> 0 | I43: ='Operating Model - IS, BS, CF'!I105 -> 0 | J43: ='Operating Model - IS, BS, CF'!J105 -> 0 | K43: ='Operating Model - IS, BS, CF'!K105 -> 0
C44: Non-Current Op Lease Repayment | G44: ='Operating Model - IS, BS, CF'!G106 -> -998 | H44: ='Operating Model - IS, BS, CF'!H106 -> -3237 | I44: ='Operating Model - IS, BS, CF'!I106 -> -3057 | J44: ='Operating Model - IS, BS, CF'!J106 -> -2985 | K44: ='Operating Model - IS, BS, CF'!K106 -> -2621
C46: Ending Cash Balance | G46: =SUM(G33:G45) -> 43269.074 | H46: =SUM(H33:H45) -> 53665.344 | I46: =SUM(I33:I45) -> 71933.738 | J46: =SUM(J33:J45) -> 98187.871 | K46: =SUM(K33:K45) -> 130558.43
C48: RCF Opening | G48: =F50 -> 0 | H48: =G50 -> 0 | I48: =H50 -> 0 | J48: =I50 -> 0 | K48: =J50 -> 0
C49: `+/- Issuance/Repayment | G49: =-MIN(G46,G48) -> 0 | H49: =-MIN(H46,H48) -> 0 | I49: =-MIN(I46,I48) -> 0 | J49: =-MIN(J46,J48) -> 0 | K49: =-MIN(K46,K48) -> 0
C50: RCF Closing | F50: 0 | G50: =SUM(G48:G49) -> 0 | H50: =SUM(H48:H49) -> 0 | I50: =SUM(I48:I49) -> 0 | J50: =SUM(J48:J49) -> 0 | K50: =SUM(K48:K49) -> 0

Sheet Disclaimer
C2: Disclaimer
C4: Although the information contained in this publication has been obtained from sources believed to be reliable, the author disclaim all warranties as to the accuracy, completeness or adequacy of such information. CFI Education shall have no liability for errors, omissions or inadequacies in the information contained herein or for interpretations thereof.

Sheet >>>
